<?xml version="1.0" ?>
<!-- =================================================================================== -->
<!-- |    This document was autogenerated by xacro from gp12.xacro                     | -->
<!-- |    EDITING THIS FILE BY HAND IS NOT RECOMMENDED                                 | -->
<!-- =================================================================================== -->
<robot name="motoman_gp12">
  <!-- link list -->
  <link name="group_1/base_link">
    <visual>
      <geometry>
        <mesh filename="package://motoman_gp12_support/meshes/visual/gp12_base_link.stl"/>
      </geometry>
      <material name="">
        <color rgba="0.12941176470588237 0.14901960784313725 0.7490196078431373 1.0"/>
      </material>
    </visual>
    <collision>
      <geometry>
        <mesh filename="package://motoman_gp12_support/meshes/collision/gp12_base_link.stl"/>
      </geometry>
    </collision>
  </link>
  <link name="group_1/link_1">
    <visual>
      <geometry>
        <mesh filename="package://motoman_gp12_support/meshes/visual/gp12_link_1_s.stl"/>
      </geometry>
      <material name="">
        <color rgba="0.12941176470588237 0.14901960784313725 0.7490196078431373 1.0"/>
      </material>
    </visual>
    <collision>
      <geometry>
        <mesh filename="package://motoman_gp12_support/meshes/collision/gp12_link_1_s.stl"/>
      </geometry>
    </collision>
  </link>
  <link name="group_1/link_2">
    <visual>
      <geometry>
        <mesh filename="package://motoman_gp12_support/meshes/visual/gp12_link_2_l.stl"/>
      </geometry>
      <material name="">
        <color rgba="0.12941176470588237 0.14901960784313725 0.7490196078431373 1.0"/>
      </material>
    </visual>
    <collision>
      <geometry>
        <mesh filename="package://motoman_gp12_support/meshes/collision/gp12_link_2_l.stl"/>
      </geometry>
    </collision>
  </link>
  <link name="group_1/link_3">
    <visual>
      <geometry>
        <mesh filename="package://motoman_gp12_support/meshes/visual/gp12_link_3_u.stl"/>
      </geometry>
      <material name="">
        <color rgba="0.12941176470588237 0.14901960784313725 0.7490196078431373 1.0"/>
      </material>
    </visual>
    <collision>
      <geometry>
        <mesh filename="package://motoman_gp12_support/meshes/collision/gp12_link_3_u.stl"/>
      </geometry>
    </collision>
  </link>
  <link name="group_1/link_4">
    <visual>
      <geometry>
        <mesh filename="package://motoman_gp12_support/meshes/visual/gp12_link_4_r.stl"/>
      </geometry>
      <material name="">
        <color rgba="0.12941176470588237 0.14901960784313725 0.7490196078431373 1.0"/>
      </material>
    </visual>
    <collision>
      <geometry>
        <mesh filename="package://motoman_gp12_support/meshes/collision/gp12_link_4_r.stl"/>
      </geometry>
    </collision>
  </link>
  <link name="group_1/link_5">
    <visual>
      <geometry>
        <mesh filename="package://motoman_gp12_support/meshes/visual/gp12_link_5_b.stl"/>
      </geometry>
      <material name="">
        <color rgba="0.12941176470588237 0.14901960784313725 0.7490196078431373 1.0"/>
      </material>
    </visual>
    <collision>
      <geometry>
        <mesh filename="package://motoman_gp12_support/meshes/collision/gp12_link_5_b.stl"/>
      </geometry>
    </collision>
  </link>
  <link name="group_1/link_6">
    <visual>
      <geometry>
        <mesh filename="package://motoman_gp12_support/meshes/visual/gp12_link_6_t.stl"/>
      </geometry>
      <material name="">
        <color rgba="0.12941176470588237 0.14901960784313725 0.7490196078431373 1.0"/>
      </material>
    </visual>
    <collision>
      <geometry>
        <mesh filename="package://motoman_gp12_support/meshes/collision/gp12_link_6_t.stl"/>
      </geometry>
    </collision>
  </link>
  <link name="group_1/tool0"/>
  <!-- end of link list -->
  <!-- joint list -->
  <joint name="group_1/joint_1" type="revolute">
    <parent link="group_1/base_link"/>
    <child link="group_1/link_1"/>
    <origin rpy="0 0 0" xyz="0 0 0.450"/>
    <axis xyz="0 0 1"/>
    <limit effort="926.10" lower="-2.9670" upper="2.9670" velocity="4.5355"/>
  </joint>
  <joint name="group_1/joint_2" type="revolute">
    <parent link="group_1/link_1"/>
    <child link="group_1/link_2"/>
    <origin rpy="0 0 0" xyz="0.155 0 0"/>
    <axis xyz="0 1 0"/>
    <limit effort="1029.00" lower="-1.5708" upper="2.7052" velocity="4.0132"/>
  </joint>
  <joint name="group_1/joint_3" type="revolute">
    <parent link="group_1/link_2"/>
    <child link="group_1/link_3"/>
    <origin rpy="0 0 0" xyz="0 0 0.614"/>
    <axis xyz="0 -1 0"/>
    <limit effort="551.25" lower="-1.4835" upper="2.6179" velocity="4.5375"/>
  </joint>
  <joint name="group_1/joint_4" type="revolute">
    <parent link="group_1/link_3"/>
    <child link="group_1/link_4"/>
    <origin rpy="0 0 0" xyz="0.640 0 0.200"/>
    <axis xyz="-1 0 0"/>
    <limit effort="89.96" lower="-3.4906" upper="3.4906" velocity="8.2007"/>
  </joint>
  <joint name="group_1/joint_5" type="revolute">
    <parent link="group_1/link_4"/>
    <child link="group_1/link_5"/>
    <origin rpy="0 0 0" xyz="0 0 0"/>
    <axis xyz="0 -1 0"/>
    <limit effort="67.03" lower="-2.6179" upper="2.6179" velocity="8.1992"/>
  </joint>
  <joint name="group_1/joint_6" type="revolute">
    <parent link="group_1/link_5"/>
    <child link="group_1/link_6"/>
    <origin rpy="0 0 0" xyz="0 0 0"/>
    <axis xyz="-1 0 0"/>
    <limit effort="33.30" lower="-7.9412" upper="7.9412" velocity="12.2143"/>
  </joint>
  <joint name="group_1/joint_6-tool0" type="fixed">
    <origin rpy="3.1415926 -1.570796 0" xyz="0.100 0 0"/>
    <parent link="group_1/link_6"/>
    <child link="group_1/tool0"/>
  </joint>
  <!-- end of joint list -->
  <!-- ROS base_link to Robot Manufacturer World Coordinates transform -->
  <link name="group_1/base"/>
  <joint name="group_1/base_link-base" type="fixed">
    <origin rpy="0 0 0" xyz="0 0 0.450"/>
    <parent link="group_1/base_link"/>
    <child link="group_1/base"/>
  </joint>
</robot>
