<?xml version="1.0" ?>
<!-- =================================================================================== -->
<!-- |    This document was autogenerated by xacro from hc10dtp_b00.xacro              | -->
<!-- |    EDITING THIS FILE BY HAND IS NOT RECOMMENDED                                 | -->
<!-- =================================================================================== -->
<robot name="motoman_hc10dtp_b00">
  <!-- link list -->
  <link name="group_1/base_link">
    <visual>
      <geometry>
        <mesh filename="package://motoman_hc10_support/meshes/hc10dt_b10/visual/base_link.dae"/>
      </geometry>
      <material name="">
        <color rgba="0.12941176470588237 0.14901960784313725 0.7490196078431373 1.0"/>
      </material>
    </visual>
    <collision>
      <geometry>
        <mesh filename="package://motoman_hc10_support/meshes/hc10dt_b10/collision/base_link.stl"/>
      </geometry>
    </collision>
  </link>
  <link name="group_1/link_1">
    <visual>
      <geometry>
        <mesh filename="package://motoman_hc10_support/meshes/hc10dt_b10/visual/link_1_s.dae"/>
      </geometry>
      <material name="">
        <color rgba="0.12941176470588237 0.14901960784313725 0.7490196078431373 1.0"/>
      </material>
    </visual>
    <collision>
      <geometry>
        <mesh filename="package://motoman_hc10_support/meshes/hc10dt_b10/collision/link_1_s.stl"/>
      </geometry>
    </collision>
  </link>
  <link name="group_1/link_2">
    <visual>
      <geometry>
        <mesh filename="package://motoman_hc10_support/meshes/hc10dt_b10/visual/link_2_l.dae"/>
      </geometry>
      <material name="">
        <color rgba="0.12941176470588237 0.14901960784313725 0.7490196078431373 1.0"/>
      </material>
    </visual>
    <collision>
      <geometry>
        <mesh filename="package://motoman_hc10_support/meshes/hc10dt_b10/collision/link_2_l.stl"/>
      </geometry>
    </collision>
  </link>
  <link name="group_1/link_3">
    <visual>
      <geometry>
        <mesh filename="package://motoman_hc10_support/meshes/hc10dt_b10/visual/link_3_u.dae"/>
      </geometry>
      <material name="">
        <color rgba="0.12941176470588237 0.14901960784313725 0.7490196078431373 1.0"/>
      </material>
    </visual>
    <collision>
      <geometry>
        <mesh filename="package://motoman_hc10_support/meshes/hc10dt_b10/collision/link_3_u.stl"/>
      </geometry>
    </collision>
  </link>
  <link name="group_1/link_4">
    <visual>
      <geometry>
        <mesh filename="package://motoman_hc10_support/meshes/hc10dt_b10/visual/link_4_r.dae"/>
      </geometry>
      <material name="">
        <color rgba="0.12941176470588237 0.14901960784313725 0.7490196078431373 1.0"/>
      </material>
    </visual>
    <collision>
      <geometry>
        <mesh filename="package://motoman_hc10_support/meshes/hc10dt_b10/collision/link_4_r.stl"/>
      </geometry>
    </collision>
  </link>
  <link name="group_1/link_5">
    <visual>
      <geometry>
        <mesh filename="package://motoman_hc10_support/meshes/hc10dt_b10/visual/link_5_b.dae"/>
      </geometry>
      <material name="">
        <color rgba="0.12941176470588237 0.14901960784313725 0.7490196078431373 1.0"/>
      </material>
    </visual>
    <collision>
      <geometry>
        <mesh filename="package://motoman_hc10_support/meshes/hc10dt_b10/collision/link_5_b.stl"/>
      </geometry>
    </collision>
  </link>
  <link name="group_1/link_6">
    <visual>
      <geometry>
        <!-- HC10 DTP reuses HC10DT-B10 meshes of all links, except for link 6 (T) -->
        <mesh filename="package://motoman_hc10_support/meshes/hc10dtp_b00/visual/link_6_t.dae"/>
      </geometry>
      <material name="">
        <color rgba="0.12941176470588237 0.14901960784313725 0.7490196078431373 1.0"/>
      </material>
    </visual>
    <collision>
      <geometry>
        <!-- HC10 DTP reuses HC10DT-B10 meshes of all links, except for link 6 (T) -->
        <mesh filename="package://motoman_hc10_support/meshes/hc10dtp_b00/collision/link_6_t.stl"/>
      </geometry>
    </collision>
  </link>
  <!-- end of link list -->
  <!-- joint list -->
  <joint name="group_1/joint_1" type="revolute">
    <parent link="group_1/base_link"/>
    <child link="group_1/link_1"/>
    <origin rpy="0 0 0" xyz="0 0 0.275"/>
    <axis xyz="0 0 1"/>
    <limit effort="368.48" lower="-3.6651914291880923" upper="3.6651914291880923" velocity="2.2689280275926285"/>
  </joint>
  <joint name="group_1/joint_2" type="revolute">
    <parent link="group_1/link_1"/>
    <child link="group_1/link_2"/>
    <origin rpy="0 0 0" xyz="0 0 0"/>
    <axis xyz="0 1 0"/>
    <limit effort="414.54" lower="-3.141592653589793" upper="3.141592653589793" velocity="2.2689280275926285"/>
  </joint>
  <joint name="group_1/joint_3" type="revolute">
    <parent link="group_1/link_2"/>
    <child link="group_1/link_3"/>
    <origin rpy="0 0 0" xyz="0 0 0.700"/>
    <axis xyz="0 -1 0"/>
    <limit effort="158.76" lower="-5.061454830783556" upper="5.061454830783556" velocity="3.141592653589793"/>
  </joint>
  <joint name="group_1/joint_4" type="revolute">
    <parent link="group_1/link_3"/>
    <child link="group_1/link_4"/>
    <origin rpy="0 0 0" xyz="0.500 0 0"/>
    <axis xyz="-1 0 0"/>
    <limit effort="41.16" lower="-3.6651914291880923" upper="3.6651914291880923" velocity="3.141592653589793"/>
  </joint>
  <joint name="group_1/joint_5" type="revolute">
    <parent link="group_1/link_4"/>
    <child link="group_1/link_5"/>
    <origin rpy="0 0 0" xyz="0 0.162 0"/>
    <axis xyz="0 -1 0"/>
    <limit effort="33.32" lower="-3.141592653589793" upper="3.141592653589793" velocity="4.363323129985824"/>
  </joint>
  <joint name="group_1/joint_6" type="revolute">
    <parent link="group_1/link_5"/>
    <child link="group_1/link_6"/>
    <origin rpy="0 0 0" xyz="0 0 0"/>
    <axis xyz="-1 0 0"/>
    <limit effort="31.36" lower="-3.6651914291880923" upper="3.6651914291880923" velocity="4.363323129985824"/>
  </joint>
  <!-- end of joint list -->
  <!-- ROS-Industrial 'flange' frame: attachment point for EEF models -->
  <link name="group_1/flange"/>
  <joint name="group_1/joint_6-flange" type="fixed">
    <origin rpy="0 0 0" xyz="0.170 0 0"/>
    <parent link="group_1/link_6"/>
    <child link="group_1/flange"/>
  </joint>
  <!-- ROS-Industrial 'tool0' frame: all-zeros tool frame -->
  <link name="group_1/tool0"/>
  <joint name="group_1/flange-tool0" type="fixed">
    <origin rpy="3.141592653589793 -1.5707963267948966 0" xyz="0 0 0"/>
    <parent link="group_1/flange"/>
    <child link="group_1/tool0"/>
  </joint>
  <!-- ROS base_link to Robot Manufacturer World Coordinates transform -->
  <link name="group_1/base"/>
  <joint name="group_1/base_link-base" type="fixed">
    <origin rpy="0 0 0" xyz="0 0 0.275"/>
    <parent link="group_1/base_link"/>
    <child link="group_1/base"/>
  </joint>
</robot>
